<?xml version="1.0" encoding="UTF-8"?>
<testng-results skipped="0" failed="1" ignored="0" total="3" passed="2">
  <reporter-output>
    <line>
      <![CDATA[[INFO] : Assertion Passed : Add New Entry functionality is working fine]]>
    </line>
    <line>
      <![CDATA[[INFO] : Assertion Passed : Not able to add duplicate number]]>
    </line>
  </reporter-output>
  <suite name="Default suite" duration-ms="37" started-at="2018-07-09T08:06:59Z" finished-at="2018-07-09T08:06:59Z">
    <groups>
    </groups>
    <test name="Default test" duration-ms="37" started-at="2018-07-09T08:06:59Z" finished-at="2018-07-09T08:06:59Z">
      <class name="testquestion1.Test_MyCollection">
        <test-method status="PASS" signature="Test1_Able_To_Add_New_Entry_In_Collection()[pri:0, instance:testquestion1.Test_MyCollection@2a2d45ba]" name="Test1_Able_To_Add_New_Entry_In_Collection" duration-ms="10" started-at="2018-07-09T08:06:59Z" description="Check Add functionality" finished-at="2018-07-09T08:06:59Z">
          <reporter-output>
            <line>
              <![CDATA[[INFO] : Assertion Passed : Add New Entry functionality is working fine]]>
            </line>
          </reporter-output>
        </test-method> <!-- Test1_Able_To_Add_New_Entry_In_Collection -->
        <test-method status="PASS" signature="Test2_Duplicate_Entry_In_Collection()[pri:0, instance:testquestion1.Test_MyCollection@2a2d45ba]" name="Test2_Duplicate_Entry_In_Collection" duration-ms="1" started-at="2018-07-09T08:06:59Z" description="Check Add functionality" finished-at="2018-07-09T08:06:59Z">
          <reporter-output>
            <line>
              <![CDATA[[INFO] : Assertion Passed : Not able to add duplicate number]]>
            </line>
          </reporter-output>
        </test-method> <!-- Test2_Duplicate_Entry_In_Collection -->
        <test-method status="FAIL" signature="Test4_DoubleCapacity()[pri:0, instance:testquestion1.Test_MyCollection@2a2d45ba]" name="Test4_DoubleCapacity" duration-ms="1" started-at="2018-07-09T08:06:59Z" description="Check Overflow Collection" finished-at="2018-07-09T08:06:59Z">
          <exception class="java.lang.AssertionError">
            <message>
              <![CDATA[Assertion Failed : Not able to add number in collection once it get fulled expected [{4,5,-4,-5,6}] but found [question1.MyCollection@731a74c]]]>
            </message>
            <full-stacktrace>
              <![CDATA[java.lang.AssertionError: Assertion Failed : Not able to add number in collection once it get fulled expected [{4,5,-4,-5,6}] but found [question1.MyCollection@731a74c]
at org.testng.Assert.fail(Assert.java:96)
at org.testng.Assert.failNotEquals(Assert.java:776)
at org.testng.Assert.assertEqualsImpl(Assert.java:137)
at org.testng.Assert.assertEquals(Assert.java:118)
at org.testng.Assert.assertEquals(Assert.java:453)
at testquestion1.Test_MyCollection.Test4_DoubleCapacity(Test_MyCollection.java:41)
at sun.reflect.NativeMethodAccessorImpl.invoke0(Native Method)
at sun.reflect.NativeMethodAccessorImpl.invoke(NativeMethodAccessorImpl.java:62)
at sun.reflect.DelegatingMethodAccessorImpl.invoke(DelegatingMethodAccessorImpl.java:43)
at java.lang.reflect.Method.invoke(Method.java:498)
at org.testng.internal.MethodInvocationHelper.invokeMethod(MethodInvocationHelper.java:124)
at org.testng.internal.Invoker.invokeMethod(Invoker.java:583)
at org.testng.internal.Invoker.invokeTestMethod(Invoker.java:719)
at org.testng.internal.Invoker.invokeTestMethods(Invoker.java:989)
at org.testng.internal.TestMethodWorker.invokeTestMethods(TestMethodWorker.java:125)
at org.testng.internal.TestMethodWorker.run(TestMethodWorker.java:109)
at org.testng.TestRunner.privateRun(TestRunner.java:648)
at org.testng.TestRunner.run(TestRunner.java:505)
at org.testng.SuiteRunner.runTest(SuiteRunner.java:455)
at org.testng.SuiteRunner.runSequentially(SuiteRunner.java:450)
at org.testng.SuiteRunner.privateRun(SuiteRunner.java:415)
at org.testng.SuiteRunner.run(SuiteRunner.java:364)
at org.testng.SuiteRunnerWorker.runSuite(SuiteRunnerWorker.java:52)
at org.testng.SuiteRunnerWorker.run(SuiteRunnerWorker.java:84)
at org.testng.TestNG.runSuitesSequentially(TestNG.java:1208)
at org.testng.TestNG.runSuitesLocally(TestNG.java:1137)
at org.testng.TestNG.runSuites(TestNG.java:1049)
at org.testng.TestNG.run(TestNG.java:1017)
at org.testng.remote.AbstractRemoteTestNG.run(AbstractRemoteTestNG.java:114)
at org.testng.remote.RemoteTestNG.initAndRun(RemoteTestNG.java:251)
at org.testng.remote.RemoteTestNG.main(RemoteTestNG.java:77)
]]>
            </full-stacktrace>
          </exception> <!-- java.lang.AssertionError -->
          <reporter-output>
          </reporter-output>
        </test-method> <!-- Test4_DoubleCapacity -->
      </class> <!-- testquestion1.Test_MyCollection -->
    </test> <!-- Default test -->
  </suite> <!-- Default suite -->
</testng-results>
